//
// Tests rethrowing an exception
//
using System;

class X {
  static Main () :  int
  {
    mutable  one = false;
    mutable  two = false;

    try {
      try {
        throw  Exception ();
      }
      catch {
                          |   _ =>  {
        one = true;
        Console.WriteLine ("Caught");
        throw;
      }
      } 
    }

    catch {
                  | _ =>  {
      two = true;
      Console.WriteLine ("Again");
    }

    }
    
    if (one && two)
    
    {{
      Console.WriteLine ("Ok");
       0;
    }
    
    } else {
      Console.WriteLine ("Failed");
     1;
               }
  }
}

/*
BEGIN-OUTPUT
Caught
Again
Ok
END-OUTPUT
*/
